{
  "artifacts": [],
  "command": "my_main",
  "experiment": {
    "base_dir": "C:\\Users\\jonas\\Documents\\epymarl\\epymarl\\src",
    "dependencies": [
      "munch==2.5.0",
      "numpy==1.23.1",
      "sacred==0.8.2",
      "torch==1.12.1"
    ],
    "mainfile": "main.py",
    "name": "pymarl",
    "repositories": [
      {
        "commit": "302fb40048c482b990c7763ce820c08b85d161bd",
        "dirty": true,
        "url": "https://github.com/JonasWild/epymarl.git"
      },
      {
        "commit": "302fb40048c482b990c7763ce820c08b85d161bd",
        "dirty": true,
        "url": "https://github.com/JonasWild/epymarl.git"
      },
      {
        "commit": "302fb40048c482b990c7763ce820c08b85d161bd",
        "dirty": true,
        "url": "https://github.com/JonasWild/epymarl.git"
      }
    ],
    "sources": [
      [
        "main.py",
        "_sources\\main_b0467e586ce8bed24edbc590c82a1e9f.py"
      ],
      [
        "run.py",
        "_sources\\run_dfd7217376a21c5ba919c90f64425233.py"
      ],
      [
        "utils\\logging.py",
        "_sources\\logging_7ddc698bb74674bae897bfdc5662ed00.py"
      ]
    ]
  },
  "fail_trace": [
    "Traceback (most recent call last):\n",
    "  File \"C:\\Users\\jonas\\Documents\\epymarl\\epymarl\\src\\runners\\episode_runner.py\", line 50, in run\n    self.reset()\n",
    "  File \"C:\\Users\\jonas\\Documents\\epymarl\\epymarl\\src\\runners\\episode_runner.py\", line 45, in reset\n    self.env.reset()\n",
    "  File \"C:\\Users\\jonas\\Documents\\epymarl\\epymarl\\smacv2\\smacv2\\env\\starcraft2\\starcraft2.py\", line 555, in reset\n    self.init_units(\n",
    "  File \"C:\\Users\\jonas\\Documents\\epymarl\\epymarl\\smacv2\\smacv2\\env\\starcraft2\\starcraft2.py\", line 2290, in init_units\n    min_unit_type = min(\n",
    "ValueError: min() arg is an empty sequence\n",
    "\nDuring handling of the above exception, another exception occurred:\n\n",
    "Traceback (most recent call last):\n",
    "  File \"C:\\Users\\jonas\\.conda\\envs\\pymarl\\lib\\site-packages\\sacred\\config\\captured_function.py\", line 42, in captured_function\n    result = wrapped(*args, **kwargs)\n",
    "  File \"C:\\Users\\jonas\\Documents\\epymarl\\epymarl\\src\\main.py\", line 48, in my_main\n    run(_run, config, _log)\n",
    "  File \"C:\\Users\\jonas\\Documents\\epymarl\\epymarl\\src\\run.py\", line 60, in run\n    run_sequential(args=args, logger=logger)\n",
    "  File \"C:\\Users\\jonas\\Documents\\epymarl\\epymarl\\src\\run.py\", line 190, in run_sequential\n    episode_batch = runner.run(test_mode=False)\n",
    "  File \"C:\\Users\\jonas\\Documents\\epymarl\\epymarl\\src\\runners\\episode_runner.py\", line 52, in run\n    print(e.with_traceback())\n",
    "TypeError: with_traceback() takes exactly one argument (0 given)\n"
  ],
  "heartbeat": "2023-06-20T07:10:18.969437",
  "host": {
    "ENV": {},
    "cpu": "Unknown",
    "gpus": {
      "driver_version": "531.79",
      "gpus": [
        {
          "model": "NVIDIA GeForce GTX 960",
          "persistence_mode": false,
          "total_memory": 2048
        }
      ]
    },
    "hostname": "DESKTOP-1HDPUO6",
    "os": [
      "Windows",
      "Windows-10-10.0.22621-SP0"
    ],
    "python_version": "3.8.16"
  },
  "meta": {
    "command": "my_main",
    "options": {
      "--beat-interval": null,
      "--capture": null,
      "--comment": null,
      "--debug": false,
      "--enforce_clean": false,
      "--file_storage": null,
      "--force": false,
      "--help": false,
      "--loglevel": null,
      "--mongo_db": null,
      "--name": null,
      "--pdb": false,
      "--print-config": false,
      "--priority": null,
      "--queue": false,
      "--s3": null,
      "--sql": null,
      "--tiny_db": null,
      "--unobserved": false,
      "COMMAND": null,
      "UPDATE": [],
      "help": false,
      "with": false
    }
  },
  "resources": [],
  "result": null,
  "start_time": "2023-06-20T07:07:58.098488",
  "status": "FAILED",
  "stop_time": "2023-06-20T07:10:18.972438"
}